Workbook

Sheet 00_기능별 현황
A1: PMS DB·API 통합 테스트 실행 현황
A2: 대상: PMS·Super Admin·DB·API 전체 연계 | 197개 케이스 | 생성일 2026-07-23 | 과거 결과 미이관
N3: 상태 | O3: 건수
A4: 전체 케이스 | C4: PASS | E4: FAIL | G4: 보류 | I4: 미실행 | K4: 실행률 | N4: PASS | O4: =C5 -> 0
A5: =COUNTA('01_전체 케이스'!$D$2:$D$198) -> 197 | C5: =COUNTIF('01_전체 케이스'!$I$2:$I$198,"PASS") -> 0 | E5: =COUNTIF('01_전체 케이스'!$I$2:$I$198,"FAIL") -> 0 | G5: =COUNTIF('01_전체 케이스'!$I$2:$I$198,"보류") -> 0 | I5: =COUNTIF('01_전체 케이스'!$I$2:$I$198,"미실행") -> 197 | K5: =IFERROR((C5+E5+G5)/A5,0) -> 0 | N5: FAIL | O5: =E5 -> 0
N6: 보류 | O6: =G5 -> 0
N7: 미실행 | O7: =I5 -> 197
A9: 기능별 상태
A10: 기능 | B10: 전체 | C10: PASS | D10: FAIL | E10: 보류 | F10: 미실행 | G10: 실행률 | H10: 종합 판정
A11: 계약·환경·스키마 | B11: =COUNTIF('01_전체 케이스'!$C$2:$C$198,A11) -> 10 | C11: =COUNTIFS('01_전체 케이스'!$C$2:$C$198,A11,'01_전체 케이스'!$I$2:$I$198,"PASS") -> 0 | D11: =COUNTIFS('01_전체 케이스'!$C$2:$C$198,A11,'01_전체 케이스'!$I$2:$I$198,"FAIL") -> 0 | E11: =COUNTIFS('01_전체 케이스'!$C$2:$C$198,A11,'01_전체 케이스'!$I$2:$I$198,"보류") -> 0 | F11: =COUNTIFS('01_전체 케이스'!$C$2:$C$198,A11,'01_전체 케이스'!$I$2:$I$198,"미실행") -> 10 | G11: =IFERROR((C11+D11+E11)/B11,0) -> 0 | H11: =IF(D11>0,"FAIL",IF(C11=B11,"PASS",IF(F11=B11,"미실행","보류"))) -> 미실행
A12: 인증·테넌트·권한 | B12: =COUNTIF('01_전체 케이스'!$C$2:$C$198,A12) -> 10 | C12: =COUNTIFS('01_전체 케이스'!$C$2:$C$198,A12,'01_전체 케이스'!$I$2:$I$198,"PASS") -> 0 | D12: =COUNTIFS('01_전체 케이스'!$C$2:$C$198,A12,'01_전체 케이스'!$I$2:$I$198,"FAIL") -> 0 | E12: =COUNTIFS('01_전체 케이스'!$C$2:$C$198,A12,'01_전체 케이스'!$I$2:$I$198,"보류") -> 0 | F12: =COUNTIFS('01_전체 케이스'!$C$2:$C$198,A12,'01_전체 케이스'!$I$2:$I$198,"미실행") -> 10 | G12: =IFERROR((C12+D12+E12)/B12,0) -> 0 | H12: =IF(D12>0,"FAIL",IF(C12=B12,"PASS",IF(F12=B12,"미실행","보류"))) -> 미실행
A13: 예약·객실·체크인·체크아웃 | B13: =COUNTIF('01_전체 케이스'!$C$2:$C$198,A13) -> 25 | C13: =COUNTIFS('01_전체 케이스'!$C$2:$C$198,A13,'01_전체 케이스'!$I$2:$I$198,"PASS") -> 0 | D13: =COUNTIFS('01_전체 케이스'!$C$2:$C$198,A13,'01_전체 케이스'!$I$2:$I$198,"FAIL") -> 0 | E13: =COUNTIFS('01_전체 케이스'!$C$2:$C$198,A13,'01_전체 케이스'!$I$2:$I$198,"보류") -> 0 | F13: =COUNTIFS('01_전체 케이스'!$C$2:$C$198,A13,'01_전체 케이스'!$I$2:$I$198,"미실행") -> 25 | G13: =IFERROR((C13+D13+E13)/B13,0) -> 0 | H13: =IF(D13>0,"FAIL",IF(C13=B13,"PASS",IF(F13=B13,"미실행","보류"))) -> 미실행
A14: 단체·고객·객실 배정 | B14: =COUNTIF('01_전체 케이스'!$C$2:$C$198,A14) -> 10 | C14: =COUNTIFS('01_전체 케이스'!$C$2:$C$198,A14,'01_전체 케이스'!$I$2:$I$198,"PASS") -> 0 | D14: =COUNTIFS('01_전체 케이스'!$C$2:$C$198,A14,'01_전체 케이스'!$I$2:$I$198,"FAIL") -> 0 | E14: =COUNTIFS('01_전체 케이스'!$C$2:$C$198,A14,'01_전체 케이스'!$I$2:$I$198,"보류") -> 0 | F14: =COUNTIFS('01_전체 케이스'!$C$2:$C$198,A14,'01_전체 케이스'!$I$2:$I$198,"미실행") -> 10 | G14: =IFERROR((C14+D14+E14)/B14,0) -> 0 | H14: =IF(D14>0,"FAIL",IF(C14=B14,"PASS",IF(F14=B14,"미실행","보류"))) -> 미실행
A15: 객실 운영·청소·시설 보수 | B15: =COUNTIF('01_전체 케이스'!$C$2:$C$198,A15) -> 8 | C15: =COUNTIFS('01_전체 케이스'!$C$2:$C$198,A15,'01_전체 케이스'!$I$2:$I$198,"PASS") -> 0 | D15: =COUNTIFS('01_전체 케이스'!$C$2:$C$198,A15,'01_전체 케이스'!$I$2:$I$198,"FAIL") -> 0 | E15: =COUNTIFS('01_전체 케이스'!$C$2:$C$198,A15,'01_전체 케이스'!$I$2:$I$198,"보류") -> 0 | F15: =COUNTIFS('01_전체 케이스'!$C$2:$C$198,A15,'01_전체 케이스'!$I$2:$I$198,"미실행") -> 8 | G15: =IFERROR((C15+D15+E15)/B15,0) -> 0 | H15: =IF(D15>0,"FAIL",IF(C15=B15,"PASS",IF(F15=B15,"미실행","보류"))) -> 미실행
A16: 부가서비스·업체·바우처 | B16: =COUNTIF('01_전체 케이스'!$C$2:$C$198,A16) -> 10 | C16: =COUNTIFS('01_전체 케이스'!$C$2:$C$198,A16,'01_전체 케이스'!$I$2:$I$198,"PASS") -> 0 | D16: =COUNTIFS('01_전체 케이스'!$C$2:$C$198,A16,'01_전체 케이스'!$I$2:$I$198,"FAIL") -> 0 | E16: =COUNTIFS('01_전체 케이스'!$C$2:$C$198,A16,'01_전체 케이스'!$I$2:$I$198,"보류") -> 0 | F16: =COUNTIFS('01_전체 케이스'!$C$2:$C$198,A16,'01_전체 케이스'!$I$2:$I$198,"미실행") -> 10 | G16: =IFERROR((C16+D16+E16)/B16,0) -> 0 | H16: =IF(D16>0,"FAIL",IF(C16=B16,"PASS",IF(F16=B16,"미실행","보류"))) -> 미실행
A17: 수납·정산·지출·마감 | B17: =COUNTIF('01_전체 케이스'!$C$2:$C$198,A17) -> 16 | C17: =COUNTIFS('01_전체 케이스'!$C$2:$C$198,A17,'01_전체 케이스'!$I$2:$I$198,"PASS") -> 0 | D17: =COUNTIFS('01_전체 케이스'!$C$2:$C$198,A17,'01_전체 케이스'!$I$2:$I$198,"FAIL") -> 0 | E17: =COUNTIFS('01_전체 케이스'!$C$2:$C$198,A17,'01_전체 케이스'!$I$2:$I$198,"보류") -> 0 | F17: =COUNTIFS('01_전체 케이스'!$C$2:$C$198,A17,'01_전체 케이스'!$I$2:$I$198,"미실행") -> 16 | G17: =IFERROR((C17+D17+E17)/B17,0) -> 0 | H17: =IF(D17>0,"FAIL",IF(C17=B17,"PASS",IF(F17=B17,"미실행","보류"))) -> 미실행
A18: 직원·CRM·설정·Admin·감사 로그 | B18: =COUNTIF('01_전체 케이스'!$C$2:$C$198,A18) -> 12 | C18: =COUNTIFS('01_전체 케이스'!$C$2:$C$198,A18,'01_전체 케이스'!$I$2:$I$198,"PASS") -> 0 | D18: =COUNTIFS('01_전체 케이스'!$C$2:$C$198,A18,'01_전체 케이스'!$I$2:$I$198,"FAIL") -> 0 | E18: =COUNTIFS('01_전체 케이스'!$C$2:$C$198,A18,'01_전체 케이스'!$I$2:$I$198,"보류") -> 0 | F18: =COUNTIFS('01_전체 케이스'!$C$2:$C$198,A18,'01_전체 케이스'!$I$2:$I$198,"미실행") -> 12 | G18: =IFERROR((C18+D18+E18)/B18,0) -> 0 | H18: =IF(D18>0,"FAIL",IF(C18=B18,"PASS",IF(F18=B18,"미실행","보류"))) -> 미실행
A19: Admin 입점·승인·계정 활성화·PMS 연계 | B19: =COUNTIF('01_전체 케이스'!$C$2:$C$198,A19) -> 25 | C19: =COUNTIFS('01_전체 케이스'!$C$2:$C$198,A19,'01_전체 케이스'!$I$2:$I$198,"PASS") -> 0 | D19: =COUNTIFS('01_전체 케이스'!$C$2:$C$198,A19,'01_전체 케이스'!$I$2:$I$198,"FAIL") -> 0 | E19: =COUNTIFS('01_전체 케이스'!$C$2:$C$198,A19,'01_전체 케이스'!$I$2:$I$198,"보류") -> 0 | F19: =COUNTIFS('01_전체 케이스'!$C$2:$C$198,A19,'01_전체 케이스'!$I$2:$I$198,"미실행") -> 25 | G19: =IFERROR((C19+D19+E19)/B19,0) -> 0 | H19: =IF(D19>0,"FAIL",IF(C19=B19,"PASS",IF(F19=B19,"미실행","보류"))) -> 미실행
A20: 동시성·장애·성능·보안·대용량 | B20: =COUNTIF('01_전체 케이스'!$C$2:$C$198,A20) -> 15 | C20: =COUNTIFS('01_전체 케이스'!$C$2:$C$198,A20,'01_전체 케이스'!$I$2:$I$198,"PASS") -> 0 | D20: =COUNTIFS('01_전체 케이스'!$C$2:$C$198,A20,'01_전체 케이스'!$I$2:$I$198,"FAIL") -> 0 | E20: =COUNTIFS('01_전체 케이스'!$C$2:$C$198,A20,'01_전체 케이스'!$I$2:$I$198,"보류") -> 0 | F20: =COUNTIFS('01_전체 케이스'!$C$2:$C$198,A20,'01_전체 케이스'!$I$2:$I$198,"미실행") -> 15 | G20: =IFERROR((C20+D20+E20)/B20,0) -> 0 | H20: =IF(D20>0,"FAIL",IF(C20=B20,"PASS",IF(F20=B20,"미실행","보류"))) -> 미실행
A21: 필수 E2E | B21: =COUNTIF('01_전체 케이스'!$C$2:$C$198,A21) -> 15 | C21: =COUNTIFS('01_전체 케이스'!$C$2:$C$198,A21,'01_전체 케이스'!$I$2:$I$198,"PASS") -> 0 | D21: =COUNTIFS('01_전체 케이스'!$C$2:$C$198,A21,'01_전체 케이스'!$I$2:$I$198,"FAIL") -> 0 | E21: =COUNTIFS('01_전체 케이스'!$C$2:$C$198,A21,'01_전체 케이스'!$I$2:$I$198,"보류") -> 0 | F21: =COUNTIFS('01_전체 케이스'!$C$2:$C$198,A21,'01_전체 케이스'!$I$2:$I$198,"미실행") -> 15 | G21: =IFERROR((C21+D21+E21)/B21,0) -> 0 | H21: =IF(D21>0,"FAIL",IF(C21=B21,"PASS",IF(F21=B21,"미실행","보류"))) -> 미실행
A22: 기존 PMS 핵심 회귀 | B22: =COUNTIF('01_전체 케이스'!$C$2:$C$198,A22) -> 41 | C22: =COUNTIFS('01_전체 케이스'!$C$2:$C$198,A22,'01_전체 케이스'!$I$2:$I$198,"PASS") -> 0 | D22: =COUNTIFS('01_전체 케이스'!$C$2:$C$198,A22,'01_전체 케이스'!$I$2:$I$198,"FAIL") -> 0 | E22: =COUNTIFS('01_전체 케이스'!$C$2:$C$198,A22,'01_전체 케이스'!$I$2:$I$198,"보류") -> 0 | F22: =COUNTIFS('01_전체 케이스'!$C$2:$C$198,A22,'01_전체 케이스'!$I$2:$I$198,"미실행") -> 41 | G22: =IFERROR((C22+D22+E22)/B22,0) -> 0 | H22: =IF(D22>0,"FAIL",IF(C22=B22,"PASS",IF(F22=B22,"미실행","보류"))) -> 미실행
A25: 판정 및 사용 원칙
A26: 1. 상태 입력은 01_전체 케이스의 상태 열에서만 수행합니다.
A27: 2. PASS는 API·DB·UI·감사 로그·새로고침 지속성 게이트를 모두 충족해야 합니다.
A28: 3. 실패 수정 후에는 fixture 초기화부터 전체 절차를 재실행하고 수정 Commit과 증거를 남깁니다.
A29: 4. 41개 기존 PMS 회귀와 15개 E2E도 각 행을 생략하지 않고 별도 판정합니다.

Sheet 01_전체 케이스
A1: No | B1: 구분 | C1: 기능 | D1: Case ID | E1: 우선순위 | F1: 화면/흐름 | G1: 입력·절차 | H1: 예상 결과 | I1: 상태 | J1: 실행일시 | K1: 실행자 | L1: 실제 결과 | M1: API 결과 | N1: DB 결과 | O1: 감사 로그 | P1: 결함 ID | Q1: 원인 | R1: 수정 내용 | S1: 수정 Commit | T1: 재시험 | U1: 증거 링크
A2: 1 | B2: DB·API | C2: 계약·환경·스키마 | D2: DBAPI-C-001 | E2: P0 | F2: 계약·환경·스키마 | G2: 배포 직후 health/version 및 업무일 API 호출 | H2: 200, build/version·server time·timezone 확인. DB 연결 실패를 200으로 숨기지 않음 | I2: 미실행
A3: 2 | B3: DB·API | C3: 계약·환경·스키마 | D3: DBAPI-C-002 | E3: P0 | F3: 계약·환경·스키마 | G3: API 명세의 모든 Endpoint를 Method·URI 기준으로 대조 | H3: 누락·중복·잘못된 Method 0건. 미구현은 404가 아니라 배포 전 차단 항목으로 기록 | I3: 미실행
A4: 3 | B4: DB·API | C4: 계약·환경·스키마 | D4: DBAPI-C-003 | E4: P0 | F4: 계약·환경·스키마 | G4: 정상 요청의 필수/선택 필드, 최대 길이, 소수점, 날짜 형식 입력 | H4: 명세 타입과 DB 타입 일치. 문자열 잘림·숫자 반올림·날짜 하루 이동 없음 | I4: 미실행
A5: 4 | B5: DB·API | C5: 계약·환경·스키마 | D5: DBAPI-C-004 | E5: P1 | F5: 계약·환경·스키마 | G5: 필수 필드 누락, 잘못된 enum, 최대 길이+1, 음수 금액 전송 | H5: 400/422와 필드별 오류. DB 저장 0건, 성공 토스트 없음 | I5: 미실행
A6: 5 | B6: DB·API | C6: 계약·환경·스키마 | D6: DBAPI-C-005 | E6: P1 | F6: 계약·환경·스키마 | G6: 없는 ID, 다른 tenant ID, 삭제된 ID 조회 | H6: 404/403 구분. 다른 tenant의 존재 여부를 메시지로 노출하지 않음 | I6: 미실행
A7: 6 | B7: DB·API | C7: 계약·환경·스키마 | D7: DBAPI-C-006 | E7: P1 | F7: 계약·환경·스키마 | G7: 목록 API의 page, size, sort, filter 조합 | H7: total/page/size/hasNext 정확, 중복·누락 없음, 정렬 안정적 | I7: 미실행
A8: 7 | B8: DB·API | C8: 계약·환경·스키마 | D8: DBAPI-C-007 | E8: P1 | F8: 계약·환경·스키마 | G8: null, 빈 문자열, 0, false가 포함된 응답 렌더링 | H8: 값이 서로 대체되지 않고 명세 의미대로 표시. 번역 키 원문 노출 없음 | I8: 미실행
A9: 8 | B9: DB·API | C9: 계약·환경·스키마 | D9: DBAPI-C-008 | E9: P1 | F9: 계약·환경·스키마 | G9: 동일 요청의 correlation ID와 server log 추적 | H9: UI 요청 1건을 API·DB·감사 로그에서 동일 ID로 추적 가능 | I9: 미실행
A10: 9 | B10: DB·API | C10: 계약·환경·스키마 | D10: DBAPI-C-009 | E10: P1 | F10: 계약·환경·스키마 | G10: API 오류 envelope와 한국어·영어 오류 표시 확인 | H10: 서버는 안정된 error code 반환, 화면은 현재 언어로 변환. 서버 한글 문자열 강제 표시 없음 | I10: 미실행
A11: 10 | B11: DB·API | C11: 계약·환경·스키마 | D11: DBAPI-C-010 | E11: P0 | F11: 계약·환경·스키마 | G11: seed 생성 후 관계 수·금액·상태 기준값 조회 | H11: fixture 건수와 합계 일치. 실행 전 기준 snapshot 저장 | I11: 미실행
A12: 11 | B12: DB·API | C12: 인증·테넌트·권한 | D12: DBAPI-A-001 | E12: P0 | F12: 인증·테넌트·권한 | G12: 근무 중 관리자 계정으로 로그인→새로고침→재접속 | H12: 200, tenant/role/permission 포함. 세션 유지, 비밀번호·token DB/응답 노출 없음 | I12: 미실행
A13: 12 | B13: DB·API | C13: 인증·테넌트·권한 | D13: DBAPI-A-002 | E13: P0 | F13: 인증·테넌트·권한 | G13: 휴직·퇴직 계정으로 로그인 | H13: 401/403, 세션 생성 0건, 로그인 화면에 사유를 과도하게 노출하지 않음 | I13: 미실행
... A198: 197 | B198: 기존 PMS 회귀 | C198: 기존 PMS 핵심 회귀 | D198: P1-ADMIN-001 | E198: P1 | F198: PMS와 Admin 호텔·공지·이벤트 연결 | G198: 입력: 공지 제목 P1 Admin Link Notice, 이벤트명 P1 Admin Link Event, 대상 tenant The Grand Saigon / 절차: Admin 호텔 상세에서 tenant ID와 호텔명을 기록한다. / 해당 호텔 대상 공지와 이벤트를 입력해 저장한다. / Admin 목록을 새로고침해 저장값을 재조회한다. / PMS에서 공지사항과 대시보드 이벤트 노출을 확인한다. / Admin에서 두 항목을 삭제하고 PMS 재조회 결과를 확인한다. / | H198: 동일 tenant ID를 사용하고 Admin 저장·삭제가 정의된 API 경로를 통해 PMS에 반영된다. 존재하지 않는 업체 광고를 클릭해 빈 상세 모달이 열리지 않는다. / | I198: 미실행

Sheet 02_Admin-PMS 연계
A1: No | B1: Case ID | C1: 단계 | D1: 화면/흐름 | E1: 데이터 연결 | F1: 입력·절차 | G1: 예상 결과 | H1: 상태 | I1: 결함 ID | J1: 증거 링크
A2: 1 | B2: DBAPI-ADM-001 | C2: Admin↔PMS | D2: Admin 입점·승인·계정 활성화·PMS 연계 | E2: applicationId → tenantId → adminUserId → sessionId | F2: 신규 호텔 `QA Onboarding Hotel {RUN_ID}`과 미사용 이메일로 입점 신청 | G2: TenantApplication 1건이 `pending`으로 생성되고 신청번호 반환. Tenant·StaffUser·로그인 세션은 아직 0건 | H2: =IFERROR(INDEX('01_전체 케이스'!$I$2:$I$198,MATCH(B2,'01_전체 케이스'!$D$2:$D$198,0)),"미실행") -> 미실행 | I2: =IFERROR(IF(INDEX('01_전체 케이스'!$P$2:$P$198,MATCH(B2,'01_전체 케이스'!$D$2:$D$198,0))="","",INDEX('01_전체 케이스'!$P$2:$P$198,MATCH(B2,'01_전체 케이스'!$D$2:$D$198,0))),"") | J2: =IFERROR(IF(INDEX('01_전체 케이스'!$U$2:$U$198,MATCH(B2,'01_전체 케이스'!$D$2:$D$198,0))="","",INDEX('01_전체 케이스'!$U$2:$U$198,MATCH(B2,'01_전체 케이스'!$D$2:$D$198,0))),"")
A3: 2 | B3: DBAPI-ADM-002 | C3: Admin↔PMS | D3: Admin 입점·승인·계정 활성화·PMS 연계 | E3: applicationId → tenantId → adminUserId → sessionId | F3: 호텔명·국가·도시·객실 수·요금제·기준 통화·담당자·전화·이메일의 필수값, 길이, 형식을 각각 위반 | G3: 필드별 4xx와 오류 코드 반환, 신청 데이터 부분 저장 0건 | H3: =IFERROR(INDEX('01_전체 케이스'!$I$2:$I$198,MATCH(B3,'01_전체 케이스'!$D$2:$D$198,0)),"미실행") -> 미실행 | I3: =IFERROR(IF(INDEX('01_전체 케이스'!$P$2:$P$198,MATCH(B3,'01_전체 케이스'!$D$2:$D$198,0))="","",INDEX('01_전체 케이스'!$P$2:$P$198,MATCH(B3,'01_전체 케이스'!$D$2:$D$198,0))),"") | J3: =IFERROR(IF(INDEX('01_전체 케이스'!$U$2:$U$198,MATCH(B3,'01_전체 케이스'!$D$2:$D$198,0))="","",INDEX('01_전체 케이스'!$U$2:$U$198,MATCH(B3,'01_전체 케이스'!$D$2:$D$198,0))),"")
A4: 3 | B4: DBAPI-ADM-003 | C4: Admin↔PMS | D4: Admin 입점·승인·계정 활성화·PMS 연계 | E4: applicationId → tenantId → adminUserId → sessionId | F4: 같은 이메일/호텔 코드로 신청을 동시에 2회 제출 | G4: 유일성 규칙에 따라 1건만 생성, 나머지는 409. 중복 tenant와 관리자 계정 없음 | H4: =IFERROR(INDEX('01_전체 케이스'!$I$2:$I$198,MATCH(B4,'01_전체 케이스'!$D$2:$D$198,0)),"미실행") -> 미실행 | I4: =IFERROR(IF(INDEX('01_전체 케이스'!$P$2:$P$198,MATCH(B4,'01_전체 케이스'!$D$2:$D$198,0))="","",INDEX('01_전체 케이스'!$P$2:$P$198,MATCH(B4,'01_전체 케이스'!$D$2:$D$198,0))),"") | J4: =IFERROR(IF(INDEX('01_전체 케이스'!$U$2:$U$198,MATCH(B4,'01_전체 케이스'!$D$2:$D$198,0))="","",INDEX('01_전체 케이스'!$U$2:$U$198,MATCH(B4,'01_전체 케이스'!$D$2:$D$198,0))),"")
A5: 4 | B5: DBAPI-ADM-004 | C5: Admin↔PMS | D5: Admin 입점·승인·계정 활성화·PMS 연계 | E5: applicationId → tenantId → adminUserId → sessionId | F5: 신청 시 입력한 자격 증명으로 승인 전 PMS 로그인 | G5: 403 `TENANT_PENDING_APPROVAL`, 세션·refresh token 발급 없음. 평문 비밀번호는 신청 테이블·응답·로그에 없음 | H5: =IFERROR(INDEX('01_전체 케이스'!$I$2:$I$198,MATCH(B5,'01_전체 케이스'!$D$2:$D$198,0)),"미실행") -> 미실행 | I5: =IFERROR(IF(INDEX('01_전체 케이스'!$P$2:$P$198,MATCH(B5,'01_전체 케이스'!$D$2:$D$198,0))="","",INDEX('01_전체 케이스'!$P$2:$P$198,MATCH(B5,'01_전체 케이스'!$D$2:$D$198,0))),"") | J5: =IFERROR(IF(INDEX('01_전체 케이스'!$U$2:$U$198,MATCH(B5,'01_전체 케이스'!$D$2:$D$198,0))="","",INDEX('01_전체 케이스'!$U$2:$U$198,MATCH(B5,'01_전체 케이스'!$D$2:$D$198,0))),"")
A6: 5 | B6: DBAPI-ADM-005 | C6: Admin↔PMS | D6: Admin 입점·승인·계정 활성화·PMS 연계 | E6: applicationId → tenantId → adminUserId → sessionId | F6: Admin 신청 목록·대시보드 KPI에서 신규 신청 검색 | G6: 동일 applicationId·호텔명·담당자·신청 시각·`pending` 상태가 표시되고 KPI가 정확히 +1 | H6: =IFERROR(INDEX('01_전체 케이스'!$I$2:$I$198,MATCH(B6,'01_전체 케이스'!$D$2:$D$198,0)),"미실행") -> 미실행 | I6: =IFERROR(IF(INDEX('01_전체 케이스'!$P$2:$P$198,MATCH(B6,'01_전체 케이스'!$D$2:$D$198,0))="","",INDEX('01_전체 케이스'!$P$2:$P$198,MATCH(B6,'01_전체 케이스'!$D$2:$D$198,0))),"") | J6: =IFERROR(IF(INDEX('01_전체 케이스'!$U$2:$U$198,MATCH(B6,'01_전체 케이스'!$D$2:$D$198,0))="","",INDEX('01_전체 케이스'!$U$2:$U$198,MATCH(B6,'01_전체 케이스'!$D$2:$D$198,0))),"")
A7: 6 | B7: DBAPI-ADM-006 | C7: Admin↔PMS | D7: Admin 입점·승인·계정 활성화·PMS 연계 | E7: applicationId → tenantId → adminUserId → sessionId | F7: Admin 신청 상세를 열어 원 신청과 대조 | G7: 국가·통화·객실 수·요금제·연락처가 신청값과 일치하고 비밀번호·credential hash는 화면/응답에서 제외 | H7: =IFERROR(INDEX('01_전체 케이스'!$I$2:$I$198,MATCH(B7,'01_전체 케이스'!$D$2:$D$198,0)),"미실행") -> 미실행 | I7: =IFERROR(IF(INDEX('01_전체 케이스'!$P$2:$P$198,MATCH(B7,'01_전체 케이스'!$D$2:$D$198,0))="","",INDEX('01_전체 케이스'!$P$2:$P$198,MATCH(B7,'01_전체 케이스'!$D$2:$D$198,0))),"") | J7: =IFERROR(IF(INDEX('01_전체 케이스'!$U$2:$U$198,MATCH(B7,'01_전체 케이스'!$D$2:$D$198,0))="","",INDEX('01_전체 케이스'!$U$2:$U$198,MATCH(B7,'01_전체 케이스'!$D$2:$D$198,0))),"")
A8: 7 | B8: DBAPI-ADM-007 | C8: Admin↔PMS | D8: Admin 입점·승인·계정 활성화·PMS 연계 | E8: applicationId → tenantId → adminUserId → sessionId | F8: 권한 있는 Admin이 사유를 입력해 신청 반려 | G8: 상태 `rejected`, 사유·처리자·처리 시각 저장, tenant/user 생성 0건, 신청자 알림 생성 | H8: =IFERROR(INDEX('01_전체 케이스'!$I$2:$I$198,MATCH(B8,'01_전체 케이스'!$D$2:$D$198,0)),"미실행") -> 미실행 | I8: =IFERROR(IF(INDEX('01_전체 케이스'!$P$2:$P$198,MATCH(B8,'01_전체 케이스'!$D$2:$D$198,0))="","",INDEX('01_전체 케이스'!$P$2:$P$198,MATCH(B8,'01_전체 케이스'!$D$2:$D$198,0))),"") | J8: =IFERROR(IF(INDEX('01_전체 케이스'!$U$2:$U$198,MATCH(B8,'01_전체 케이스'!$D$2:$D$198,0))="","",INDEX('01_전체 케이스'!$U$2:$U$198,MATCH(B8,'01_전체 케이스'!$D$2:$D$198,0))),"")
A9: 8 | B9: DBAPI-ADM-008 | C9: Admin↔PMS | D9: Admin 입점·승인·계정 활성화·PMS 연계 | E9: applicationId → tenantId → adminUserId → sessionId | F9: 반려된 신청의 계정으로 로그인 | G9: 403 `TENANT_APPLICATION_REJECTED`, 반려 사유 확인 경로 제공, 세션 없음 | H9: =IFERROR(INDEX('01_전체 케이스'!$I$2:$I$198,MATCH(B9,'01_전체 케이스'!$D$2:$D$198,0)),"미실행") -> 미실행 | I9: =IFERROR(IF(INDEX('01_전체 케이스'!$P$2:$P$198,MATCH(B9,'01_전체 케이스'!$D$2:$D$198,0))="","",INDEX('01_전체 케이스'!$P$2:$P$198,MATCH(B9,'01_전체 케이스'!$D$2:$D$198,0))),"") | J9: =IFERROR(IF(INDEX('01_전체 케이스'!$U$2:$U$198,MATCH(B9,'01_전체 케이스'!$D$2:$D$198,0))="","",INDEX('01_전체 케이스'!$U$2:$U$198,MATCH(B9,'01_전체 케이스'!$D$2:$D$198,0))),"")
A10: 9 | B10: DBAPI-ADM-009 | C10: Admin↔PMS | D10: Admin 입점·승인·계정 활성화·PMS 연계 | E10: applicationId → tenantId → adminUserId → sessionId | F10: 반려 사유를 보완해 같은 신청을 재제출 | G10: revision 또는 이전 applicationId 연결 이력 보존, 상태 `pending`, 활성 신청은 1건, 반려 이력 삭제 금지 | H10: =IFERROR(INDEX('01_전체 케이스'!$I$2:$I$198,MATCH(B10,'01_전체 케이스'!$D$2:$D$198,0)),"미실행") -> 미실행 | I10: =IFERROR(IF(INDEX('01_전체 케이스'!$P$2:$P$198,MATCH(B10,'01_전체 케이스'!$D$2:$D$198,0))="","",INDEX('01_전체 케이스'!$P$2:$P$198,MATCH(B10,'01_전체 케이스'!$D$2:$D$198,0))),"") | J10: =IFERROR(IF(INDEX('01_전체 케이스'!$U$2:$U$198,MATCH(B10,'01_전체 케이스'!$D$2:$D$198,0))="","",INDEX('01_전체 케이스'!$U$2:$U$198,MATCH(B10,'01_전체 케이스'!$D$2:$D$198,0))),"")
A11: 10 | B11: DBAPI-ADM-010 | C11: Admin↔PMS | D11: Admin 입점·승인·계정 활성화·PMS 연계 | E11: applicationId → tenantId → adminUserId → sessionId | F11: 권한 있는 Admin이 pending 신청 승인 | G11: 단일 transaction으로 Tenant·TenantSetting·계약/요금제·최초 Tenant Admin·역할/권한·활성화 정보 생성, application `approved` | H11: =IFERROR(INDEX('01_전체 케이스'!$I$2:$I$198,MATCH(B11,'01_전체 케이스'!$D$2:$D$198,0)),"미실행") -> 미실행 | I11: =IFERROR(IF(INDEX('01_전체 케이스'!$P$2:$P$198,MATCH(B11,'01_전체 케이스'!$D$2:$D$198,0))="","",INDEX('01_전체 케이스'!$P$2:$P$198,MATCH(B11,'01_전체 케이스'!$D$2:$D$198,0))),"") | J11: =IFERROR(IF(INDEX('01_전체 케이스'!$U$2:$U$198,MATCH(B11,'01_전체 케이스'!$D$2:$D$198,0))="","",INDEX('01_전체 케이스'!$U$2:$U$198,MATCH(B11,'01_전체 케이스'!$D$2:$D$198,0))),"")
A12: 11 | B12: DBAPI-ADM-011 | C12: Admin↔PMS | D12: Admin 입점·승인·계정 활성화·PMS 연계 | E12: applicationId → tenantId → adminUserId → sessionId | F12: 동일 승인 버튼을 연속 클릭하고 같은 요청을 재전송 | G12: 같은 tenantId/userId 반환, Tenant·관리자 계정·계약 각 1건, 승인 감사 로그 1건 | H12: =IFERROR(INDEX('01_전체 케이스'!$I$2:$I$198,MATCH(B12,'01_전체 케이스'!$D$2:$D$198,0)),"미실행") -> 미실행 | I12: =IFERROR(IF(INDEX('01_전체 케이스'!$P$2:$P$198,MATCH(B12,'01_전체 케이스'!$D$2:$D$198,0))="","",INDEX('01_전체 케이스'!$P$2:$P$198,MATCH(B12,'01_전체 케이스'!$D$2:$D$198,0))),"") | J12: =IFERROR(IF(INDEX('01_전체 케이스'!$U$2:$U$198,MATCH(B12,'01_전체 케이스'!$D$2:$D$198,0))="","",INDEX('01_전체 케이스'!$U$2:$U$198,MATCH(B12,'01_전체 케이스'!$D$2:$D$198,0))),"")
A13: 12 | B13: DBAPI-ADM-012 | C13: Admin↔PMS | D13: Admin 입점·승인·계정 활성화·PMS 연계 | E13: applicationId → tenantId → adminUserId → sessionId | F13: 승인 transaction 중 최초 관리자 생성 실패 주입 | G13: 신청은 `pending` 유지, Tenant·설정·계약 포함 전체 rollback, 재시도 가능 | H13: =IFERROR(INDEX('01_전체 케이스'!$I$2:$I$198,MATCH(B13,'01_전체 케이스'!$D$2:$D$198,0)),"미실행") -> 미실행 | I13: =IFERROR(IF(INDEX('01_전체 케이스'!$P$2:$P$198,MATCH(B13,'01_전체 케이스'!$D$2:$D$198,0))="","",INDEX('01_전체 케이스'!$P$2:$P$198,MATCH(B13,'01_전체 케이스'!$D$2:$D$198,0))),"") | J13: =IFERROR(IF(INDEX('01_전체 케이스'!$U$2:$U$198,MATCH(B13,'01_전체 케이스'!$D$2:$D$198,0))="","",INDEX('01_전체 케이스'!$U$2:$U$198,MATCH(B13,'01_전체 케이스'!$D$2:$D$198,0))),"")
... A33: 32 | B33: E2E-DBAPI-015 | C33: Admin↔PMS | D33: PMS 미사용 호텔의 파트너 포털 분기 | E33: applicationId → PartnerAccount → PartnerProperty | F33: PMS 미사용 유형으로 입점 신청하고 Admin이 승인한다. / 파트너 계정을 활성화해 별도 포털에 로그인한다. / 숙소·상품·가격·재고·예약·정산 기능을 사용한다. / PMS URL과 PMS 전용 API 접근을 시도한다. | G33: PartnerAccount/PartnerProperty에만 연결되고 PMS 운영 기능은 403 또는 미노출이다. Admin에서는 PMS tenant와 구분해 관리된다. | H33: =IFERROR(INDEX('01_전체 케이스'!$I$2:$I$198,MATCH(B33,'01_전체 케이스'!$D$2:$D$198,0)),"미실행") -> 미실행 | I33: =IFERROR(IF(INDEX('01_전체 케이스'!$P$2:$P$198,MATCH(B33,'01_전체 케이스'!$D$2:$D$198,0))="","",INDEX('01_전체 케이스'!$P$2:$P$198,MATCH(B33,'01_전체 케이스'!$D$2:$D$198,0))),"") | J33: =IFERROR(IF(INDEX('01_전체 케이스'!$U$2:$U$198,MATCH(B33,'01_전체 케이스'!$D$2:$D$198,0))="","",INDEX('01_전체 케이스'!$U$2:$U$198,MATCH(B33,'01_전체 케이스'!$D$2:$D$198,0))),"")

Sheet 03_E2E 결과
A1: No | B1: Case ID | C1: 시나리오 | D1: 핵심 절차 | E1: 최종 기대 결과 | F1: 상태 | G1: 실제 결과 | H1: 결함 ID | I1: 재시험 | J1: 증거 링크
A2: 1 | B2: E2E-DBAPI-001 | C2: 개인 고객 전체 사이클 | D2: TD-ROOM-CLEAN에 D0~D+2 예약을 생성한다. / 고객과 동반 투숙객을 연결하고 D0에 체크인한다. / POS·골프·렌터카·음식점·기타를 각 1건 등록한다. / 현금과 카드로 나누어 수납한다. / D+1 대신 D0에 조기 체크아웃한다. / 정산 완료 후 청소 상태를 확인하고 청소 완료 처리한다. | E2: 예약은 checked_out이며 no-show가 아니다. 객실은 vacant/clean, Folio balance=0, 5개 부가서비스와 결제 이력이 보존되고 고객 이력·감사 로그가 연결된다. | F2: =IFERROR(INDEX('01_전체 케이스'!$I$2:$I$198,MATCH(B2,'01_전체 케이스'!$D$2:$D$198,0)),"미실행") -> 미실행 | G2: =IFERROR(IF(INDEX('01_전체 케이스'!$L$2:$L$198,MATCH(B2,'01_전체 케이스'!$D$2:$D$198,0))="","",INDEX('01_전체 케이스'!$L$2:$L$198,MATCH(B2,'01_전체 케이스'!$D$2:$D$198,0))),"") | H2: =IFERROR(IF(INDEX('01_전체 케이스'!$P$2:$P$198,MATCH(B2,'01_전체 케이스'!$D$2:$D$198,0))="","",INDEX('01_전체 케이스'!$P$2:$P$198,MATCH(B2,'01_전체 케이스'!$D$2:$D$198,0))),"") | I2: =IFERROR(IF(INDEX('01_전체 케이스'!$T$2:$T$198,MATCH(B2,'01_전체 케이스'!$D$2:$D$198,0))="","",INDEX('01_전체 케이스'!$T$2:$T$198,MATCH(B2,'01_전체 케이스'!$D$2:$D$198,0))),"") | J2: =IFERROR(IF(INDEX('01_전체 케이스'!$U$2:$U$198,MATCH(B2,'01_전체 케이스'!$D$2:$D$198,0))="","",INDEX('01_전체 케이스'!$U$2:$U$198,MATCH(B2,'01_전체 케이스'!$D$2:$D$198,0))),"")
A3: 2 | B3: E2E-DBAPI-002 | C3: 청소·점검 차단과 복구 | D3: 청소 필요 객실의 예약 경고에서 취소와 계속을 각각 실행한다. / 점검 ticket을 생성하고 예약·체크인을 차단한다. / ticket 완료 후 청소 필요를 확인하고 청소 완료로 전환한다. / 같은 객실 예약과 체크인을 재시도한다. | E3: 차단 중 저장 0건, 복구 후 1건. 상태 전환 순서와 감사 로그가 일치한다. | F3: =IFERROR(INDEX('01_전체 케이스'!$I$2:$I$198,MATCH(B3,'01_전체 케이스'!$D$2:$D$198,0)),"미실행") -> 미실행 | G3: =IFERROR(IF(INDEX('01_전체 케이스'!$L$2:$L$198,MATCH(B3,'01_전체 케이스'!$D$2:$D$198,0))="","",INDEX('01_전체 케이스'!$L$2:$L$198,MATCH(B3,'01_전체 케이스'!$D$2:$D$198,0))),"") | H3: =IFERROR(IF(INDEX('01_전체 케이스'!$P$2:$P$198,MATCH(B3,'01_전체 케이스'!$D$2:$D$198,0))="","",INDEX('01_전체 케이스'!$P$2:$P$198,MATCH(B3,'01_전체 케이스'!$D$2:$D$198,0))),"") | I3: =IFERROR(IF(INDEX('01_전체 케이스'!$T$2:$T$198,MATCH(B3,'01_전체 케이스'!$D$2:$D$198,0))="","",INDEX('01_전체 케이스'!$T$2:$T$198,MATCH(B3,'01_전체 케이스'!$D$2:$D$198,0))),"") | J3: =IFERROR(IF(INDEX('01_전체 케이스'!$U$2:$U$198,MATCH(B3,'01_전체 케이스'!$D$2:$D$198,0))="","",INDEX('01_전체 케이스'!$U$2:$U$198,MATCH(B3,'01_전체 케이스'!$D$2:$D$198,0))),"")
A4: 3 | B4: E2E-DBAPI-003 | C4: 단체 행사 전체 사이클 | D4: 단체 업체와 행사를 만들고 3실을 배정한다. / 대표·동반·미배정 투숙객을 연결한다. / 체크인 후 동일 골프·렌터카 서비스와 개별 POS를 등록한다. / 객실별 수납과 단체 정산을 완료한다. / 통계에서 해당 기간을 조회한다. | E4: 객실·투숙객 없는 배정에는 서비스가 없고, 객실/서비스/총액이 Folio와 통계에서 일치한다. | F4: =IFERROR(INDEX('01_전체 케이스'!$I$2:$I$198,MATCH(B4,'01_전체 케이스'!$D$2:$D$198,0)),"미실행") -> 미실행 | G4: =IFERROR(IF(INDEX('01_전체 케이스'!$L$2:$L$198,MATCH(B4,'01_전체 케이스'!$D$2:$D$198,0))="","",INDEX('01_전체 케이스'!$L$2:$L$198,MATCH(B4,'01_전체 케이스'!$D$2:$D$198,0))),"") | H4: =IFERROR(IF(INDEX('01_전체 케이스'!$P$2:$P$198,MATCH(B4,'01_전체 케이스'!$D$2:$D$198,0))="","",INDEX('01_전체 케이스'!$P$2:$P$198,MATCH(B4,'01_전체 케이스'!$D$2:$D$198,0))),"") | I4: =IFERROR(IF(INDEX('01_전체 케이스'!$T$2:$T$198,MATCH(B4,'01_전체 케이스'!$D$2:$D$198,0))="","",INDEX('01_전체 케이스'!$T$2:$T$198,MATCH(B4,'01_전체 케이스'!$D$2:$D$198,0))),"") | J4: =IFERROR(IF(INDEX('01_전체 케이스'!$U$2:$U$198,MATCH(B4,'01_전체 케이스'!$D$2:$D$198,0))="","",INDEX('01_전체 케이스'!$U$2:$U$198,MATCH(B4,'01_전체 케이스'!$D$2:$D$198,0))),"")
A5: 4 | B5: E2E-DBAPI-004 | C5: 지출·시재·일일 마감 | D5: 현금 PHP 지출, 카드 USD 지출, 현금 KRW 지출을 등록한다. / 현금 수납과 환불을 등록한다. / 시재 상세를 조회하고 일일 마감한다. / 지출 1건을 수정/취소해야 하는 경우 조정 정책을 실행한다. | E5: 통화별 원금이 분리되고 현금만 시재에 반영된다. 마감 합계와 원장이 일치하며 과거 마감이 조용히 변경되지 않는다. | F5: =IFERROR(INDEX('01_전체 케이스'!$I$2:$I$198,MATCH(B5,'01_전체 케이스'!$D$2:$D$198,0)),"미실행") -> 미실행 | G5: =IFERROR(IF(INDEX('01_전체 케이스'!$L$2:$L$198,MATCH(B5,'01_전체 케이스'!$D$2:$D$198,0))="","",INDEX('01_전체 케이스'!$L$2:$L$198,MATCH(B5,'01_전체 케이스'!$D$2:$D$198,0))),"") | H5: =IFERROR(IF(INDEX('01_전체 케이스'!$P$2:$P$198,MATCH(B5,'01_전체 케이스'!$D$2:$D$198,0))="","",INDEX('01_전체 케이스'!$P$2:$P$198,MATCH(B5,'01_전체 케이스'!$D$2:$D$198,0))),"") | I5: =IFERROR(IF(INDEX('01_전체 케이스'!$T$2:$T$198,MATCH(B5,'01_전체 케이스'!$D$2:$D$198,0))="","",INDEX('01_전체 케이스'!$T$2:$T$198,MATCH(B5,'01_전체 케이스'!$D$2:$D$198,0))),"") | J5: =IFERROR(IF(INDEX('01_전체 케이스'!$U$2:$U$198,MATCH(B5,'01_전체 케이스'!$D$2:$D$198,0))="","",INDEX('01_전체 케이스'!$U$2:$U$198,MATCH(B5,'01_전체 케이스'!$D$2:$D$198,0))),"")
A6: 5 | B6: E2E-DBAPI-005 | C6: 정산·부가서비스 되돌리기 권한 | D6: 관리자와 프런트 계정으로 각각 정산 완료/미완료, 부가서비스 완료/미완료를 시도한다. / 역할 기능 권한을 변경하고 재로그인 후 반복한다. | E6: 화면과 API 권한이 일치하고 허용된 변경만 저장된다. 모든 성공 전환은 감사 로그에 남는다. | F6: =IFERROR(INDEX('01_전체 케이스'!$I$2:$I$198,MATCH(B6,'01_전체 케이스'!$D$2:$D$198,0)),"미실행") -> 미실행 | G6: =IFERROR(IF(INDEX('01_전체 케이스'!$L$2:$L$198,MATCH(B6,'01_전체 케이스'!$D$2:$D$198,0))="","",INDEX('01_전체 케이스'!$L$2:$L$198,MATCH(B6,'01_전체 케이스'!$D$2:$D$198,0))),"") | H6: =IFERROR(IF(INDEX('01_전체 케이스'!$P$2:$P$198,MATCH(B6,'01_전체 케이스'!$D$2:$D$198,0))="","",INDEX('01_전체 케이스'!$P$2:$P$198,MATCH(B6,'01_전체 케이스'!$D$2:$D$198,0))),"") | I6: =IFERROR(IF(INDEX('01_전체 케이스'!$T$2:$T$198,MATCH(B6,'01_전체 케이스'!$D$2:$D$198,0))="","",INDEX('01_전체 케이스'!$T$2:$T$198,MATCH(B6,'01_전체 케이스'!$D$2:$D$198,0))),"") | J6: =IFERROR(IF(INDEX('01_전체 케이스'!$U$2:$U$198,MATCH(B6,'01_전체 케이스'!$D$2:$D$198,0))="","",INDEX('01_전체 케이스'!$U$2:$U$198,MATCH(B6,'01_전체 케이스'!$D$2:$D$198,0))),"")
A7: 6 | B7: E2E-DBAPI-006 | C7: Admin→PMS 연결 | D7: Admin에서 tenant 정보·공지·광고·상태를 변경한다. / 대상 PMS와 비대상 PMS에서 재조회한다. / tenant를 중지·재활성화한다. | E7: 대상 조건, 캐시 무효화, 접근 차단, 재활성화가 일치하며 다른 tenant에 노출되지 않는다. | F7: =IFERROR(INDEX('01_전체 케이스'!$I$2:$I$198,MATCH(B7,'01_전체 케이스'!$D$2:$D$198,0)),"미실행") -> 미실행 | G7: =IFERROR(IF(INDEX('01_전체 케이스'!$L$2:$L$198,MATCH(B7,'01_전체 케이스'!$D$2:$D$198,0))="","",INDEX('01_전체 케이스'!$L$2:$L$198,MATCH(B7,'01_전체 케이스'!$D$2:$D$198,0))),"") | H7: =IFERROR(IF(INDEX('01_전체 케이스'!$P$2:$P$198,MATCH(B7,'01_전체 케이스'!$D$2:$D$198,0))="","",INDEX('01_전체 케이스'!$P$2:$P$198,MATCH(B7,'01_전체 케이스'!$D$2:$D$198,0))),"") | I7: =IFERROR(IF(INDEX('01_전체 케이스'!$T$2:$T$198,MATCH(B7,'01_전체 케이스'!$D$2:$D$198,0))="","",INDEX('01_전체 케이스'!$T$2:$T$198,MATCH(B7,'01_전체 케이스'!$D$2:$D$198,0))),"") | J7: =IFERROR(IF(INDEX('01_전체 케이스'!$U$2:$U$198,MATCH(B7,'01_전체 케이스'!$D$2:$D$198,0))="","",INDEX('01_전체 케이스'!$U$2:$U$198,MATCH(B7,'01_전체 케이스'!$D$2:$D$198,0))),"")
A8: 7 | B8: E2E-DBAPI-007 | C8: 네트워크 실패·중복 제출 복구 | D8: 예약, 부가서비스, 수납, 비품 구매 각각에서 응답 지연→중복 클릭→오프라인→재접속을 실행한다. | E8: 각 업무 데이터는 1건만 존재하고 사용자는 최종 성공/실패 상태를 확인할 수 있다. | F8: =IFERROR(INDEX('01_전체 케이스'!$I$2:$I$198,MATCH(B8,'01_전체 케이스'!$D$2:$D$198,0)),"미실행") -> 미실행 | G8: =IFERROR(IF(INDEX('01_전체 케이스'!$L$2:$L$198,MATCH(B8,'01_전체 케이스'!$D$2:$D$198,0))="","",INDEX('01_전체 케이스'!$L$2:$L$198,MATCH(B8,'01_전체 케이스'!$D$2:$D$198,0))),"") | H8: =IFERROR(IF(INDEX('01_전체 케이스'!$P$2:$P$198,MATCH(B8,'01_전체 케이스'!$D$2:$D$198,0))="","",INDEX('01_전체 케이스'!$P$2:$P$198,MATCH(B8,'01_전체 케이스'!$D$2:$D$198,0))),"") | I8: =IFERROR(IF(INDEX('01_전체 케이스'!$T$2:$T$198,MATCH(B8,'01_전체 케이스'!$D$2:$D$198,0))="","",INDEX('01_전체 케이스'!$T$2:$T$198,MATCH(B8,'01_전체 케이스'!$D$2:$D$198,0))),"") | J8: =IFERROR(IF(INDEX('01_전체 케이스'!$U$2:$U$198,MATCH(B8,'01_전체 케이스'!$D$2:$D$198,0))="","",INDEX('01_전체 케이스'!$U$2:$U$198,MATCH(B8,'01_전체 케이스'!$D$2:$D$198,0))),"")
A9: 8 | B9: E2E-DBAPI-008 | C9: 다국어·통화·타임존 왕복 | D9: TEN-QA-PH와 TEN-QA-VN에서 같은 시나리오를 한국어와 영어로 실행한다. / 언어 변경 후 새로고침·메뉴 이동·modal 재오픈을 수행한다. / D0 자정 경계에서 예약·지출·감사 시각을 비교한다. | E9: 사용자 입력은 불변, 라벨과 오류만 번역, 기준 통화와 업무일은 tenant 설정을 따른다. | F9: =IFERROR(INDEX('01_전체 케이스'!$I$2:$I$198,MATCH(B9,'01_전체 케이스'!$D$2:$D$198,0)),"미실행") -> 미실행 | G9: =IFERROR(IF(INDEX('01_전체 케이스'!$L$2:$L$198,MATCH(B9,'01_전체 케이스'!$D$2:$D$198,0))="","",INDEX('01_전체 케이스'!$L$2:$L$198,MATCH(B9,'01_전체 케이스'!$D$2:$D$198,0))),"") | H9: =IFERROR(IF(INDEX('01_전체 케이스'!$P$2:$P$198,MATCH(B9,'01_전체 케이스'!$D$2:$D$198,0))="","",INDEX('01_전체 케이스'!$P$2:$P$198,MATCH(B9,'01_전체 케이스'!$D$2:$D$198,0))),"") | I9: =IFERROR(IF(INDEX('01_전체 케이스'!$T$2:$T$198,MATCH(B9,'01_전체 케이스'!$D$2:$D$198,0))="","",INDEX('01_전체 케이스'!$T$2:$T$198,MATCH(B9,'01_전체 케이스'!$D$2:$D$198,0))),"") | J9: =IFERROR(IF(INDEX('01_전체 케이스'!$U$2:$U$198,MATCH(B9,'01_전체 케이스'!$D$2:$D$198,0))="","",INDEX('01_전체 케이스'!$U$2:$U$198,MATCH(B9,'01_전체 케이스'!$D$2:$D$198,0))),"")
A10: 9 | B10: E2E-DBAPI-009 | C10: 호텔 가입부터 PMS 첫 업무까지 | D10: 공개 입점 신청 화면에서 QA Onboarding Hotel {RUN_ID}을 신청한다. / 승인 전 로그인 차단과 Admin 신청 목록/KPI 반영을 확인한다. / Admin이 상세 내용을 검토하고 승인한다. / 신청자가 계정을 활성화하고 PMS에 최초 로그인한다. / 호텔명·언어·타임존·통화·객실을 설정한 뒤 고객과 예약 1건을 등록한다. | E10: applicationId·tenantId·관리자 userId·sessionId·첫 reservationId가 한 흐름으로 연결된다. 승인 전에는 PMS 데이터가 없고, 승인 후에는 해당 tenant 데이터만 접근 가능하다. | F10: =IFERROR(INDEX('01_전체 케이스'!$I$2:$I$198,MATCH(B10,'01_전체 케이스'!$D$2:$D$198,0)),"미실행") -> 미실행 | G10: =IFERROR(IF(INDEX('01_전체 케이스'!$L$2:$L$198,MATCH(B10,'01_전체 케이스'!$D$2:$D$198,0))="","",INDEX('01_전체 케이스'!$L$2:$L$198,MATCH(B10,'01_전체 케이스'!$D$2:$D$198,0))),"") | H10: =IFERROR(IF(INDEX('01_전체 케이스'!$P$2:$P$198,MATCH(B10,'01_전체 케이스'!$D$2:$D$198,0))="","",INDEX('01_전체 케이스'!$P$2:$P$198,MATCH(B10,'01_전체 케이스'!$D$2:$D$198,0))),"") | I10: =IFERROR(IF(INDEX('01_전체 케이스'!$T$2:$T$198,MATCH(B10,'01_전체 케이스'!$D$2:$D$198,0))="","",INDEX('01_전체 케이스'!$T$2:$T$198,MATCH(B10,'01_전체 케이스'!$D$2:$D$198,0))),"") | J10: =IFERROR(IF(INDEX('01_전체 케이스'!$U$2:$U$198,MATCH(B10,'01_전체 케이스'!$D$2:$D$198,0))="","",INDEX('01_전체 케이스'!$U$2:$U$198,MATCH(B10,'01_전체 케이스'!$D$2:$D$198,0))),"")
A11: 10 | B11: E2E-DBAPI-010 | C11: 입점 반려·보완·재신청·승인 | D11: 필수 정보가 부족한 신청을 Admin에서 구체적 사유로 반려한다. / 신청자는 사유를 확인하고 정보를 보완해 재신청한다. / Admin은 변경 내용을 비교한 뒤 승인한다. / 신청자는 활성화 및 PMS 로그인을 완료한다. | E11: 반려 이력과 revision이 보존되며 활성 신청·tenant·최초 관리자 계정은 각각 1건이다. | F11: =IFERROR(INDEX('01_전체 케이스'!$I$2:$I$198,MATCH(B11,'01_전체 케이스'!$D$2:$D$198,0)),"미실행") -> 미실행 | G11: =IFERROR(IF(INDEX('01_전체 케이스'!$L$2:$L$198,MATCH(B11,'01_전체 케이스'!$D$2:$D$198,0))="","",INDEX('01_전체 케이스'!$L$2:$L$198,MATCH(B11,'01_전체 케이스'!$D$2:$D$198,0))),"") | H11: =IFERROR(IF(INDEX('01_전체 케이스'!$P$2:$P$198,MATCH(B11,'01_전체 케이스'!$D$2:$D$198,0))="","",INDEX('01_전체 케이스'!$P$2:$P$198,MATCH(B11,'01_전체 케이스'!$D$2:$D$198,0))),"") | I11: =IFERROR(IF(INDEX('01_전체 케이스'!$T$2:$T$198,MATCH(B11,'01_전체 케이스'!$D$2:$D$198,0))="","",INDEX('01_전체 케이스'!$T$2:$T$198,MATCH(B11,'01_전체 케이스'!$D$2:$D$198,0))),"") | J11: =IFERROR(IF(INDEX('01_전체 케이스'!$U$2:$U$198,MATCH(B11,'01_전체 케이스'!$D$2:$D$198,0))="","",INDEX('01_전체 케이스'!$U$2:$U$198,MATCH(B11,'01_전체 케이스'!$D$2:$D$198,0))),"")
A12: 11 | B12: E2E-DBAPI-011 | C12: Admin 공지 게시부터 PMS 읽음까지 | D12: Admin이 한국어/영어 공지를 초안으로 저장한다. / 신규 승인 호텔만 대상으로 기간을 설정해 게시한다. / 대상/비대상 PMS에서 노출을 비교하고 대상 호텔에서 상세를 읽는다. / 게시를 취소하거나 만료시킨 뒤 다시 조회한다. | E12: 대상·언어·기간 조건과 read receipt가 정확하며 비대상 노출과 게시 취소 후 잔존 캐시는 0건이다. | F12: =IFERROR(INDEX('01_전체 케이스'!$I$2:$I$198,MATCH(B12,'01_전체 케이스'!$D$2:$D$198,0)),"미실행") -> 미실행 | G12: =IFERROR(IF(INDEX('01_전체 케이스'!$L$2:$L$198,MATCH(B12,'01_전체 케이스'!$D$2:$D$198,0))="","",INDEX('01_전체 케이스'!$L$2:$L$198,MATCH(B12,'01_전체 케이스'!$D$2:$D$198,0))),"") | H12: =IFERROR(IF(INDEX('01_전체 케이스'!$P$2:$P$198,MATCH(B12,'01_전체 케이스'!$D$2:$D$198,0))="","",INDEX('01_전체 케이스'!$P$2:$P$198,MATCH(B12,'01_전체 케이스'!$D$2:$D$198,0))),"") | I12: =IFERROR(IF(INDEX('01_전체 케이스'!$T$2:$T$198,MATCH(B12,'01_전체 케이스'!$D$2:$D$198,0))="","",INDEX('01_전체 케이스'!$T$2:$T$198,MATCH(B12,'01_전체 케이스'!$D$2:$D$198,0))),"") | J12: =IFERROR(IF(INDEX('01_전체 케이스'!$U$2:$U$198,MATCH(B12,'01_전체 케이스'!$D$2:$D$198,0))="","",INDEX('01_전체 케이스'!$U$2:$U$198,MATCH(B12,'01_전체 케이스'!$D$2:$D$198,0))),"")
A13: 12 | B13: E2E-DBAPI-012 | C13: Admin 광고 계약·게시·노출·중지 | D13: 광고주/캠페인과 계약 정보를 등록하고 초안 상태를 확인한다. / 서비스 유형·대상 호텔·게시 기간·노출 위치를 지정해 게시한다. / PMS 대시보드에서 광고 상세를 열고 문의를 등록한다. / Admin에서 조회·문의·과금을 대조하고 광고를 일시중지한다. | E13: 초안/비대상/기간 외에는 미노출이고, 게시 데이터·상세·문의·과금이 같은 campaignId로 연결된다. 중지 후 빈 상세 팝업은 나타나지 않는다. | F13: =IFERROR(INDEX('01_전체 케이스'!$I$2:$I$198,MATCH(B13,'01_전체 케이스'!$D$2:$D$198,0)),"미실행") -> 미실행 | G13: =IFERROR(IF(INDEX('01_전체 케이스'!$L$2:$L$198,MATCH(B13,'01_전체 케이스'!$D$2:$D$198,0))="","",INDEX('01_전체 케이스'!$L$2:$L$198,MATCH(B13,'01_전체 케이스'!$D$2:$D$198,0))),"") | H13: =IFERROR(IF(INDEX('01_전체 케이스'!$P$2:$P$198,MATCH(B13,'01_전체 케이스'!$D$2:$D$198,0))="","",INDEX('01_전체 케이스'!$P$2:$P$198,MATCH(B13,'01_전체 케이스'!$D$2:$D$198,0))),"") | I13: =IFERROR(IF(INDEX('01_전체 케이스'!$T$2:$T$198,MATCH(B13,'01_전체 케이스'!$D$2:$D$198,0))="","",INDEX('01_전체 케이스'!$T$2:$T$198,MATCH(B13,'01_전체 케이스'!$D$2:$D$198,0))),"") | J13: =IFERROR(IF(INDEX('01_전체 케이스'!$U$2:$U$198,MATCH(B13,'01_전체 케이스'!$D$2:$D$198,0))="","",INDEX('01_전체 케이스'!$U$2:$U$198,MATCH(B13,'01_전체 케이스'!$D$2:$D$198,0))),"")
... A16: 15 | B16: E2E-DBAPI-015 | C16: PMS 미사용 호텔의 파트너 포털 분기 | D16: PMS 미사용 유형으로 입점 신청하고 Admin이 승인한다. / 파트너 계정을 활성화해 별도 포털에 로그인한다. / 숙소·상품·가격·재고·예약·정산 기능을 사용한다. / PMS URL과 PMS 전용 API 접근을 시도한다. | E16: PartnerAccount/PartnerProperty에만 연결되고 PMS 운영 기능은 403 또는 미노출이다. Admin에서는 PMS tenant와 구분해 관리된다. | F16: =IFERROR(INDEX('01_전체 케이스'!$I$2:$I$198,MATCH(B16,'01_전체 케이스'!$D$2:$D$198,0)),"미실행") -> 미실행 | G16: =IFERROR(IF(INDEX('01_전체 케이스'!$L$2:$L$198,MATCH(B16,'01_전체 케이스'!$D$2:$D$198,0))="","",INDEX('01_전체 케이스'!$L$2:$L$198,MATCH(B16,'01_전체 케이스'!$D$2:$D$198,0))),"") | H16: =IFERROR(IF(INDEX('01_전체 케이스'!$P$2:$P$198,MATCH(B16,'01_전체 케이스'!$D$2:$D$198,0))="","",INDEX('01_전체 케이스'!$P$2:$P$198,MATCH(B16,'01_전체 케이스'!$D$2:$D$198,0))),"") | I16: =IFERROR(IF(INDEX('01_전체 케이스'!$T$2:$T$198,MATCH(B16,'01_전체 케이스'!$D$2:$D$198,0))="","",INDEX('01_전체 케이스'!$T$2:$T$198,MATCH(B16,'01_전체 케이스'!$D$2:$D$198,0))),"") | J16: =IFERROR(IF(INDEX('01_전체 케이스'!$U$2:$U$198,MATCH(B16,'01_전체 케이스'!$D$2:$D$198,0))="","",INDEX('01_전체 케이스'!$U$2:$U$198,MATCH(B16,'01_전체 케이스'!$D$2:$D$198,0))),"")

Sheet 04_결함 및 수정
A1: 결함 ID | B1: Case ID | C1: 기능 | D1: 심각도 | E1: 상태 | F1: 결함 요약 | G1: 재현 절차 | H1: 원인 | I1: 수정 파일/내용 | J1: 수정 Commit | K1: 재시험 결과 | L1: 증거 링크 | M1: 담당자 | N1: 등록일 | O1: 완료일

Sheet 05_페이지_API_DB 추적
A1: Page ID | B1: 구분 | C1: 화면 경로 | D1: 제어 ID/라벨 | E1: API Alias | F1: DB 엔티티 | G1: 관련 Case ID | H1: 예상 연계 | I1: 상태 | J1: 비고
A2: PG-PMS-001 | B2: PMS | C2: dashboard/index.html | D2: 세션 분기, 로그인 이동 | E2: IP-AUTH | F2: AUTH · StaffUser/Role/Session | H2: 올바른 초기 경로와 언어 | I2: 미실행
A3: PG-PMS-002 | B3: PMS | C3: dashboard/login.html | D3: 이메일, 비밀번호, 로그인 | E3: IP-AUTH | F3: AUTH · StaffUser/Role/Session | H3: 역할별 첫 화면, 휴직·퇴직 차단 | I3: 미실행
A4: PG-PMS-003 | B4: PMS | C4: dashboard/dashboard.html | D4: KPI, 광고 배너·상세, 일정, 알림 링크 | E4: IP-RES, IP-ADMIN | F4: RES · Reservation/Guest/Folio / ADMIN · TenantApplication/Notice/Campaign/Support | G4: DBAPI-ADM-* | H4: 예약/정산 카운트와 연결 화면 | I4: 미실행
A5: PG-PMS-004 | B5: PMS | C5: dashboard/notifications.html | D5: 읽음, 전체 읽음, 필터, 링크 이동 | E5: IP-RES, IP-ADMIN | F5: RES · Reservation/Guest/Folio / ADMIN · TenantApplication/Notice/Campaign/Support | G5: DBAPI-ADM-* | H5: 대상 업무 화면과 읽음 지속성 | I5: 미실행
A6: PG-PMS-005 | B6: PMS | C6: dashboard/crm/guests.html | D6: 검색, 등록, 상세, 수정, 삭제/차단, 이력 | E6: IP-CRM | F6: GUEST · Guest/TierHistory | H6: 예약 투숙객 선택과 고객 이력 | I6: 미실행
A7: PG-PMS-006 | B7: PMS | C7: dashboard/crm/membership.html | D7: 등급 기준, 혜택, 수정, 상태 | E7: IP-CRM | F7: GUEST · Guest/TierHistory | H7: 고객 상세와 멤버십 표시 | I7: 미실행
A8: PG-PMS-007 | B8: PMS | C8: dashboard/crm/tier-history.html | D8: 월 필터, 유형, 검색, 다운로드 | E8: IP-CRM | F8: GUEST · Guest/TierHistory | H8: 등급 변경 건수와 상세 이력 | I8: 미실행
A9: PG-PMS-008 | B9: PMS | C9: dashboard/frontdesk/reservation-board.html | D9: 상태 필터, 검색, 청소 선택, 신규 예약, 상세, 체크인, 플랫카드 | E9: IP-RES, IP-ROOM | F9: RES · Reservation/Guest/Folio / ROOM · Room/RoomStatus | G9: DBAPI-R-* | H9: 목록·타임라인·객실·정산·감사 | I9: 미실행
A10: PG-PMS-009 | B10: PMS | C10: dashboard/frontdesk/reservation-list.html | D10: 동일 카운트 필터, 검색, 정렬, 상세 | E10: IP-RES | F10: RES · Reservation/Guest/Folio | G10: DBAPI-R-* | H10: 보드와 카운트·상태 일치 | I10: 미실행
A11: PG-PMS-010 | B11: PMS | C11: dashboard/frontdesk/reservation-timeline.html | D11: 날짜 이동, 오늘, 예약 블록, 그룹 블록 | E11: IP-RES, IP-GROUP | F11: RES · Reservation/Guest/Folio / GROUP · GroupCompany/GroupEvent | G11: DBAPI-R-* | H11: 보드와 일정·색상·병합 일치 | I11: 미실행
A12: PG-PMS-011 | B12: PMS | C12: dashboard/frontdesk/checkin.html | D12: 금일 체크인, 투숙객, 객실, 체크인/차단 | E12: IP-RES, IP-ROOM | F12: RES · Reservation/Guest/Folio / ROOM · Room/RoomStatus | G12: DBAPI-R-* | H12: 보드 투숙 상태와 객실 점유 | I12: 미실행
A13: PG-PMS-012 | B13: PMS | C13: dashboard/frontdesk/groups_companies.html | D13: 업체 등록, 편집, 삭제 제약, 이벤트, 거래 통계 | E13: IP-GROUP | F13: GROUP · GroupCompany/GroupEvent | H13: 이벤트·정산·통계 합계 | I13: 미실행
A14: PG-PMS-013 | B14: PMS | C14: dashboard/frontdesk/groups_blocks.html | D14: 검색, 상태, 이벤트 생성·상세 | E14: IP-GROUP | F14: GROUP · GroupCompany/GroupEvent | H14: 업체 카드와 이벤트 수 | I14: 미실행
A15: PG-PMS-014 | B15: PMS | C15: dashboard/frontdesk/groups_block_detail.html | D15: 개요, 객실 배정, 투숙객, 정산, 변경 이력 | E15: IP-GROUP, IP-ROOM | F15: GROUP · GroupCompany/GroupEvent / ROOM · Room/RoomStatus | H15: 예약·타임라인·정산·감사 | I15: 미실행
A16: PG-PMS-015 | B16: PMS | C16: dashboard/operations/rooms.html | D16: 객실 필터, 상태, 상세, 점유 정보 | E16: IP-ROOM | F16: ROOM · Room/RoomStatus | H16: 예약·청소·시설 상태 일치 | I16: 미실행
A17: PG-PMS-016 | B17: PMS | C17: dashboard/operations/room-setup.html | D17: 객실/유형/건물 등록·편집·삭제 | E17: IP-ROOM | F17: ROOM · Room/RoomStatus | H17: 객실 관리와 예약 선택 목록 | I17: 미실행
A18: PG-PMS-017 | B18: PMS | C18: dashboard/operations/housekeeping.html | D18: 보기 전환, 우선순위, 담당자, 상태 변경 | E18: IP-HK | F18: HK · HousekeepingTask/RoomStatus | H18: 예약 보드 청소 색상·체크인 경고 | I18: 미실행
A19: PG-PMS-018 | B19: PMS | C19: dashboard/operations/maintenance.html | D19: 등록, 우선순위, 담당자, 수정, 완료, 삭제 | E19: IP-MAINT | F19: MAINT · MaintenanceTicket/RoomStatus | H19: 예약 차단·객실 점검 상태 | I19: 미실행
A20: PG-PMS-019 | B20: PMS | C20: dashboard/operations/ancillary.html | D20: 카테고리, 투숙객 필터, 상세, 등록, 완료/미완료 | E20: IP-ANC | F20: ANC · Vendor/Item/Order | H20: 정산·바우처·감사 로그 | I20: 미실행
A21: PG-PMS-020 | B21: PMS | C21: dashboard/operations/ancillary-vendors.html | D21: 업체·항목 카테고리, 등록·수정·삭제, 바우처 양식 | E21: IP-ANC | F21: ANC · Vendor/Item/Order | H21: 부가서비스 등록 선택값 | I21: 미실행
A22: PG-PMS-021 | B22: PMS | C22: dashboard/operations/unified-pos.html | D22: POS 주문, 항목, 수량, 투숙객, 완료/취소 | E22: IP-ANC | F22: ANC · Vendor/Item/Order | H22: 부가서비스·정산·감사 | I22: 미실행
A23: PG-PMS-022 | B23: PMS | C23: dashboard/operations/pos.html | D23: POS 업체·메뉴·주문 | E23: IP-ANC | F23: ANC · Vendor/Item/Order | H23: 통합 POS와 정산 분류 | I23: 미실행
A24: PG-PMS-023 | B24: PMS | C24: dashboard/operations/golf.html | D24: 골프 업체·항목·바우처 | E24: IP-ANC | F24: ANC · Vendor/Item/Order | H24: 부가서비스 골프 필터와 출력 | I24: 미실행
... A26: PG-PMS-025 | B26: PMS | C26: dashboard/operations/room-service.html | D26: 메뉴, 주문, 객실/투숙객, 상태 | E26: IP-ANC | F26: ANC · Vendor/Item/Order | H26: 부가서비스·정산 반영 | I26: 미실행
A27: PG-PMS-026 | B27: PMS | C27: dashboard/operations/events.html | D27: 이벤트 목록·상세·기간·상태 | E27: IP-ADMIN | F27: ADMIN · TenantApplication/Notice/Campaign/Support | G27: DBAPI-ADM-* | H27: 대시보드 광고/이벤트 상세 | I27: 미실행
A28: PG-PMS-027 | B28: PMS | C28: dashboard/operations/rates.html | D28: 객실 유형, 기간, 요금, 저장 | E28: IP-ROOM | F28: ROOM · Room/RoomStatus | H28: 신규 예약 기본 금액 | I28: 미실행
A29: PG-PMS-028 | B29: PMS | C29: dashboard/operations/settlement-status.html | D29: 상태 필터, 카드/행, 수납, 완료, 상세, 미완료 전환 | E29: IP-FOLIO | F29: FOLIO · Folio/Payment/Refund | H29: Folio·객실 청소·감사 로그 | I29: 미실행
A30: PG-PMS-029 | B30: PMS | C30: dashboard/operations/folio.html | D30: 검색, 목록, 상세, 결제·환불·정산 | E30: IP-FOLIO | F30: FOLIO · Folio/Payment/Refund | H30: 정산 현황과 처리 이력 | I30: 미실행
A31: PG-PMS-030 | B31: PMS | C31: dashboard/operations/folio-chart.html | D31: 기간, 통화, 카테고리, 차트 | E31: IP-FOLIO, IP-EXP | F31: FOLIO · Folio/Payment/Refund / EXP · ExpensePurchase/CashTransaction | H31: Folio·지출 합계 | I31: 미실행
A32: PG-PMS-031 | B32: PMS | C32: dashboard/operations/expense-purchases.html | D32: 기간, 검색, 등록, 수정, 삭제, 통화 | E32: IP-EXP | F32: EXP · ExpensePurchase/CashTransaction | H32: KPI·시재·마감·감사 | I32: 미실행
A33: PG-PMS-032 | B33: PMS | C33: dashboard/operations/night-audit.html | D33: 마감일, 시작 시재, 입금, 출금, 시재 내역, 마감 | E33: IP-EXP, IP-FOLIO | F33: EXP · ExpensePurchase/CashTransaction / FOLIO · Folio/Payment/Refund | H33: closing log·지출·정산 합계 | I33: 미실행
A34: PG-PMS-033 | B34: PMS | C34: dashboard/operations/closing-log.html | D34: 기간, 마감 상세, 재조회 | E34: IP-EXP, IP-FOLIO | F34: EXP · ExpensePurchase/CashTransaction / FOLIO · Folio/Payment/Refund | H34: night audit 결과 지속성 | I34: 미실행
A35: PG-PMS-034 | B35: PMS | C35: dashboard/operations/reports.html | D35: 기간, 보고서 종류, 다운로드 | E35: 전체 팩 | F35: 전체 팩 | H35: 원천 화면 합계와 파일 값 | I35: 미실행
A36: PG-PMS-035 | B36: PMS | C36: dashboard/settings/settings.html | D36: 호텔 정보, 통화, 언어, 로고, 저장 | E36: IP-ADMIN | F36: ADMIN · TenantApplication/Notice/Campaign/Support | G36: DBAPI-ADM-* | H36: 헤더·출력물·통화 선택 | I36: 미실행
A37: PG-PMS-036 | B37: PMS | C37: dashboard/settings/staff.html | D37: 직원 등록, 편집, 역할, 상태, 비밀번호, 삭제 | E37: IP-STAFF | F37: STAFF · StaffUser/Role/Permission | H37: 로그인·권한·구매자 목록 | I37: 미실행
A38: PG-PMS-037 | B38: PMS | C38: dashboard/settings/roles.html | D38: 역할, 메뉴 권한, 기능 권한, 저장 | E38: IP-STAFF | F38: STAFF · StaffUser/Role/Permission | H38: 역할별 메뉴·정산/부가 되돌리기 | I38: 미실행
A39: PG-PMS-038 | B39: PMS | C39: dashboard/settings/billing.html | D39: 결제 설정, 수단, 저장 | E39: IP-ADMIN | F39: ADMIN · TenantApplication/Notice/Campaign/Support | G39: DBAPI-ADM-* | H39: 결제/정산 기본 설정 | I39: 미실행
A40: PG-PMS-039 | B40: PMS | C40: dashboard/settings/audit-logs.html | D40: 검색, 유형, 기간, 페이지네이션 | E40: 전체 팩 | F40: 전체 팩 | H40: 모든 변경 작업의 행·화면명 | I40: 미실행
A41: PG-PMS-040 | B41: PMS | C41: dashboard/settings/notices.html | D41: 공지 목록, 상세, 읽음 | E41: IP-ADMIN | F41: ADMIN · TenantApplication/Notice/Campaign/Support | G41: DBAPI-ADM-* | H41: Admin 공지와 표시 일치 | I41: 미실행
...

Sheet 99_코드맵
A1: 코드 구분 | B1: 코드 | C1: 설명
A2: 결과 | B2: PASS | C2: API·DB·UI·감사·지속성 게이트 모두 충족
A3: 결과 | B3: FAIL | C3: 예상 결과 또는 필수 게이트 중 하나 이상 불일치
A4: 결과 | B4: 보류 | C4: 환경·외부 의존성 때문에 실행 불가
A5: 결과 | B5: 미실행 | C5: 아직 실행하지 않음
A6: 우선순위 | B6: P0 | C6: 데이터 유실·권한·중복·핵심 운영 차단
A7: 우선순위 | B7: P1 | C7: 주요 CRUD·상태·금액·연계 오류
A8: 우선순위 | B8: P2 | C8: 다국어·표시·카운트·레이아웃 오류
A9: 우선순위 | B9: P3 | C9: 경미한 문구·정렬
A10: 재시험 | B10: PASS | C10: 수정 배포 후 동일 케이스 전체 절차 통과
A11: 재시험 | B11: FAIL | C11: 재현되거나 인접 회귀 실패
A12: 재시험 | B12: 미실행 | C12: 수정 후 아직 재시험하지 않음
